2016-06-10 00:10:30,749 DEBUG Initializing LogsDownloader
2016-06-10 00:10:30,755 INFO LogsDownloader initializing is done
2016-06-10 00:10:30,786 DEBUG The last known downloaded file is 448_2344.log
2016-06-10 00:10:30,789 DEBUG Will now try to download 448_2345.log
2016-06-10 00:10:32,096 ERROR Could not find file https://logs1.incapsula.com/448_290059/448_2345.log. Response code is 404
2016-06-10 00:10:32,098 INFO Sleeping for 20 seconds until next file download retry number 1 out of 3
2016-06-10 00:10:52,904 ERROR Could not find file https://logs1.incapsula.com/448_290059/448_2345.log. Response code is 404
2016-06-10 00:10:53,332 INFO Sleeping for 20 seconds until next file download retry number 2 out of 3
2016-06-10 00:11:13,792 ERROR Could not find file https://logs1.incapsula.com/448_290059/448_2345.log. Response code is 404
2016-06-10 00:11:13,798 INFO Sleeping for 20 seconds until next file download retry number 3 out of 3
2016-06-10 00:11:34,272 ERROR Could not find file https://logs1.incapsula.com/448_290059/448_2345.log. Response code is 404
2016-06-10 00:11:34,279 INFO Could not get log file 448_2345.log. It could be that the log file does not exist yet.
2016-06-10 00:11:34,286 INFO Sleeping for 30 seconds before trying to fetch logs again...
2016-06-10 00:12:04,301 DEBUG The last known downloaded file is 448_2344.log
2016-06-10 00:12:04,305 DEBUG Will now try to download 448_2345.log
2016-06-10 00:12:04,798 ERROR Could not find file https://logs1.incapsula.com/448_290059/448_2345.log. Response code is 404
2016-06-10 00:12:04,802 INFO Sleeping for 20 seconds until next file download retry number 1 out of 3
2016-06-10 00:12:25,234 ERROR Could not find file https://logs1.incapsula.com/448_290059/448_2345.log. Response code is 404
2016-06-10 00:12:25,246 INFO Sleeping for 20 seconds until next file download retry number 2 out of 3
2016-06-10 00:12:45,740 ERROR Could not find file https://logs1.incapsula.com/448_290059/448_2345.log. Response code is 404
2016-06-10 00:12:45,746 INFO Sleeping for 20 seconds until next file download retry number 3 out of 3
2016-06-10 00:34:13,315 DEBUG Initializing LogsDownloader
2016-06-10 00:34:13,318 INFO LogsDownloader initializing is done
2016-06-10 00:34:13,321 INFO No last downloaded file is found - downloading index file and starting to download all the log files in it
2016-06-10 00:34:13,322 INFO Downloading logs index file...
2016-06-10 00:34:14,598 INFO Successfully downloaded file from URL https://logs1.incapsula.com/448_290059/logs.index
2016-06-10 00:34:14,812 INFO No last index found, will now scan the entire index...
2016-06-10 00:34:15,265 INFO Successfully downloaded file from URL https://logs1.incapsula.com/448_290059/448_30587.log
2016-06-10 00:34:15,385 INFO Saving file 448_30587.log locally to the 'fail' folder global name 'today' is not defined Traceback (most recent call last):
  File "LogsDownloader.py", line 198, in handle_file
    self.handle_log_decrypted_content(logfile, decrypted_file)
  File "LogsDownloader.py", line 242, in handle_log_decrypted_content
    local_file_nf = today.strftime(self.config.PROCESS_DIR + '%Y%m%d%H%M.log')
NameError: global name 'today' is not defined

2016-06-10 00:34:15,411 INFO Saved file 448_30587.log locally to the 'fail' folder
2016-06-10 00:34:15,414 WARNING Skipping File 448_30587.log
2016-06-10 00:34:15,855 INFO Successfully downloaded file from URL https://logs1.incapsula.com/448_290059/448_30588.log
2016-06-10 00:34:15,964 INFO Saving file 448_30588.log locally to the 'fail' folder global name 'today' is not defined Traceback (most recent call last):
  File "LogsDownloader.py", line 198, in handle_file
    self.handle_log_decrypted_content(logfile, decrypted_file)
  File "LogsDownloader.py", line 242, in handle_log_decrypted_content
    local_file_nf = today.strftime(self.config.PROCESS_DIR + '%Y%m%d%H%M.log')
NameError: global name 'today' is not defined

2016-06-10 00:34:15,980 INFO Saved file 448_30588.log locally to the 'fail' folder
2016-06-10 00:34:15,986 WARNING Skipping File 448_30588.log
2016-06-10 00:34:16,433 INFO Successfully downloaded file from URL https://logs1.incapsula.com/448_290059/448_30589.log
2016-06-10 00:34:17,088 INFO Saving file 448_30589.log locally to the 'fail' folder global name 'today' is not defined Traceback (most recent call last):
  File "LogsDownloader.py", line 198, in handle_file
    self.handle_log_decrypted_content(logfile, decrypted_file)
  File "LogsDownloader.py", line 242, in handle_log_decrypted_content
    local_file_nf = today.strftime(self.config.PROCESS_DIR + '%Y%m%d%H%M.log')
NameError: global name 'today' is not defined

2016-06-10 00:34:17,677 INFO Saved file 448_30589.log locally to the 'fail' folder
2016-06-10 00:34:17,710 WARNING Skipping File 448_30589.log
2016-06-10 00:34:18,280 INFO Successfully downloaded file from URL https://logs1.incapsula.com/448_290059/448_30590.log
2016-06-10 00:34:18,967 INFO Saving file 448_30590.log locally to the 'fail' folder global name 'today' is not defined Traceback (most recent call last):
  File "LogsDownloader.py", line 198, in handle_file
    self.handle_log_decrypted_content(logfile, decrypted_file)
  File "LogsDownloader.py", line 242, in handle_log_decrypted_content
    local_file_nf = today.strftime(self.config.PROCESS_DIR + '%Y%m%d%H%M.log')
NameError: global name 'today' is not defined

2016-06-10 00:34:18,989 INFO Saved file 448_30590.log locally to the 'fail' folder
2016-06-10 00:34:18,993 WARNING Skipping File 448_30590.log
2016-06-10 00:34:19,809 INFO Successfully downloaded file from URL https://logs1.incapsula.com/448_290059/448_30591.log
2016-06-10 00:34:19,911 INFO Saving file 448_30591.log locally to the 'fail' folder global name 'today' is not defined Traceback (most recent call last):
  File "LogsDownloader.py", line 198, in handle_file
    self.handle_log_decrypted_content(logfile, decrypted_file)
  File "LogsDownloader.py", line 242, in handle_log_decrypted_content
    local_file_nf = today.strftime(self.config.PROCESS_DIR + '%Y%m%d%H%M.log')
NameError: global name 'today' is not defined

2016-06-10 00:34:19,950 INFO Saved file 448_30591.log locally to the 'fail' folder
2016-06-10 00:34:19,969 WARNING Skipping File 448_30591.log
2016-06-10 00:34:20,505 INFO Successfully downloaded file from URL https://logs1.incapsula.com/448_290059/448_30592.log
2016-06-10 00:34:20,619 INFO Saving file 448_30592.log locally to the 'fail' folder global name 'today' is not defined Traceback (most recent call last):
  File "LogsDownloader.py", line 198, in handle_file
    self.handle_log_decrypted_content(logfile, decrypted_file)
  File "LogsDownloader.py", line 242, in handle_log_decrypted_content
    local_file_nf = today.strftime(self.config.PROCESS_DIR + '%Y%m%d%H%M.log')
NameError: global name 'today' is not defined

2016-06-10 00:34:20,653 INFO Saved file 448_30592.log locally to the 'fail' folder
2016-06-10 00:34:20,671 WARNING Skipping File 448_30592.log
2016-06-10 00:34:21,098 INFO Successfully downloaded file from URL https://logs1.incapsula.com/448_290059/448_30593.log
2016-06-10 00:34:21,365 INFO Saving file 448_30593.log locally to the 'fail' folder global name 'today' is not defined Traceback (most recent call last):
  File "LogsDownloader.py", line 198, in handle_file
    self.handle_log_decrypted_content(logfile, decrypted_file)
  File "LogsDownloader.py", line 242, in handle_log_decrypted_content
    local_file_nf = today.strftime(self.config.PROCESS_DIR + '%Y%m%d%H%M.log')
NameError: global name 'today' is not defined

2016-06-10 00:34:21,384 INFO Saved file 448_30593.log locally to the 'fail' folder
2016-06-10 00:34:21,397 WARNING Skipping File 448_30593.log
2016-06-10 00:34:21,770 INFO Successfully downloaded file from URL https://logs1.incapsula.com/448_290059/448_30594.log
2016-06-10 00:34:21,898 INFO Saving file 448_30594.log locally to the 'fail' folder global name 'today' is not defined Traceback (most recent call last):
  File "LogsDownloader.py", line 198, in handle_file
    self.handle_log_decrypted_content(logfile, decrypted_file)
  File "LogsDownloader.py", line 242, in handle_log_decrypted_content
    local_file_nf = today.strftime(self.config.PROCESS_DIR + '%Y%m%d%H%M.log')
NameError: global name 'today' is not defined

2016-06-10 00:34:21,940 INFO Saved file 448_30594.log locally to the 'fail' folder
2016-06-10 00:34:21,956 WARNING Skipping File 448_30594.log
2016-06-10 00:34:22,591 INFO Successfully downloaded file from URL https://logs1.incapsula.com/448_290059/448_30595.log
2016-06-10 00:34:22,690 INFO Saving file 448_30595.log locally to the 'fail' folder global name 'today' is not defined Traceback (most recent call last):
  File "LogsDownloader.py", line 198, in handle_file
    self.handle_log_decrypted_content(logfile, decrypted_file)
  File "LogsDownloader.py", line 242, in handle_log_decrypted_content
    local_file_nf = today.strftime(self.config.PROCESS_DIR + '%Y%m%d%H%M.log')
NameError: global name 'today' is not defined

2016-06-10 00:34:22,709 INFO Saved file 448_30595.log locally to the 'fail' folder
2016-06-10 00:34:22,713 WARNING Skipping File 448_30595.log
2016-06-10 00:34:23,153 INFO Successfully downloaded file from URL https://logs1.incapsula.com/448_290059/448_30596.log
2016-06-10 00:34:23,257 INFO Saving file 448_30596.log locally to the 'fail' folder global name 'today' is not defined Traceback (most recent call last):
  File "LogsDownloader.py", line 198, in handle_file
    self.handle_log_decrypted_content(logfile, decrypted_file)
  File "LogsDownloader.py", line 242, in handle_log_decrypted_content
    local_file_nf = today.strftime(self.config.PROCESS_DIR + '%Y%m%d%H%M.log')
NameError: global name 'today' is not defined

2016-06-10 00:34:23,273 INFO Saved file 448_30596.log locally to the 'fail' folder
2016-06-10 00:34:23,280 WARNING Skipping File 448_30596.log
2016-06-10 00:34:23,732 INFO Successfully downloaded file from URL https://logs1.incapsula.com/448_290059/448_30597.log
2016-06-10 00:34:24,382 INFO Saving file 448_30597.log locally to the 'fail' folder global name 'today' is not defined Traceback (most recent call last):
  File "LogsDownloader.py", line 198, in handle_file
    self.handle_log_decrypted_content(logfile, decrypted_file)
  File "LogsDownloader.py", line 242, in handle_log_decrypted_content
    local_file_nf = today.strftime(self.config.PROCESS_DIR + '%Y%m%d%H%M.log')
NameError: global name 'today' is not defined

2016-06-10 00:34:24,410 INFO Saved file 448_30597.log locally to the 'fail' folder
2016-06-10 00:34:24,413 WARNING Skipping File 448_30597.log
2016-06-10 00:34:25,457 INFO Successfully downloaded file from URL https://logs1.incapsula.com/448_290059/448_30598.log
2016-06-10 00:34:26,102 INFO Saving file 448_30598.log locally to the 'fail' folder global name 'today' is not defined Traceback (most recent call last):
  File "LogsDownloader.py", line 198, in handle_file
    self.handle_log_decrypted_content(logfile, decrypted_file)
  File "LogsDownloader.py", line 242, in handle_log_decrypted_content
    local_file_nf = today.strftime(self.config.PROCESS_DIR + '%Y%m%d%H%M.log')
NameError: global name 'today' is not defined

2016-06-10 00:34:26,125 INFO Saved file 448_30598.log locally to the 'fail' folder
2016-06-10 00:34:26,132 WARNING Skipping File 448_30598.log
2016-06-10 00:34:26,575 INFO Successfully downloaded file from URL https://logs1.incapsula.com/448_290059/448_30599.log
2016-06-10 00:34:26,596 INFO Saving file 448_30599.log locally to the 'fail' folder global name 'today' is not defined Traceback (most recent call last):
  File "LogsDownloader.py", line 198, in handle_file
    self.handle_log_decrypted_content(logfile, decrypted_file)
  File "LogsDownloader.py", line 242, in handle_log_decrypted_content
    local_file_nf = today.strftime(self.config.PROCESS_DIR + '%Y%m%d%H%M.log')
NameError: global name 'today' is not defined

2016-06-10 00:34:26,612 INFO Saved file 448_30599.log locally to the 'fail' folder
2016-06-10 00:34:26,624 WARNING Skipping File 448_30599.log
2016-06-10 00:34:27,019 INFO Successfully downloaded file from URL https://logs1.incapsula.com/448_290059/448_30600.log
2016-06-10 00:34:27,140 INFO Saving file 448_30600.log locally to the 'fail' folder global name 'today' is not defined Traceback (most recent call last):
  File "LogsDownloader.py", line 198, in handle_file
    self.handle_log_decrypted_content(logfile, decrypted_file)
  File "LogsDownloader.py", line 242, in handle_log_decrypted_content
    local_file_nf = today.strftime(self.config.PROCESS_DIR + '%Y%m%d%H%M.log')
NameError: global name 'today' is not defined

2016-06-10 00:34:27,148 INFO Saved file 448_30600.log locally to the 'fail' folder
2016-06-10 00:34:27,155 WARNING Skipping File 448_30600.log
2016-06-10 00:34:28,377 INFO Successfully downloaded file from URL https://logs1.incapsula.com/448_290059/448_30601.log
2016-06-10 00:34:28,487 INFO Saving file 448_30601.log locally to the 'fail' folder global name 'today' is not defined Traceback (most recent call last):
  File "LogsDownloader.py", line 198, in handle_file
    self.handle_log_decrypted_content(logfile, decrypted_file)
  File "LogsDownloader.py", line 242, in handle_log_decrypted_content
    local_file_nf = today.strftime(self.config.PROCESS_DIR + '%Y%m%d%H%M.log')
NameError: global name 'today' is not defined

2016-06-10 00:34:28,585 INFO Saved file 448_30601.log locally to the 'fail' folder
2016-06-10 00:34:28,607 WARNING Skipping File 448_30601.log
2016-06-10 00:34:28,999 INFO Successfully downloaded file from URL https://logs1.incapsula.com/448_290059/448_30602.log
2016-06-10 00:34:30,048 INFO Saving file 448_30602.log locally to the 'fail' folder global name 'today' is not defined Traceback (most recent call last):
  File "LogsDownloader.py", line 198, in handle_file
    self.handle_log_decrypted_content(logfile, decrypted_file)
  File "LogsDownloader.py", line 242, in handle_log_decrypted_content
    local_file_nf = today.strftime(self.config.PROCESS_DIR + '%Y%m%d%H%M.log')
NameError: global name 'today' is not defined

2016-06-10 00:34:30,572 INFO Saved file 448_30602.log locally to the 'fail' folder
2016-06-10 00:34:30,585 WARNING Skipping File 448_30602.log
2016-06-10 00:34:31,065 INFO Successfully downloaded file from URL https://logs1.incapsula.com/448_290059/448_30603.log
2016-06-10 00:34:31,773 INFO Saving file 448_30603.log locally to the 'fail' folder global name 'today' is not defined Traceback (most recent call last):
  File "LogsDownloader.py", line 198, in handle_file
    self.handle_log_decrypted_content(logfile, decrypted_file)
  File "LogsDownloader.py", line 242, in handle_log_decrypted_content
    local_file_nf = today.strftime(self.config.PROCESS_DIR + '%Y%m%d%H%M.log')
NameError: global name 'today' is not defined

2016-06-10 00:34:31,799 INFO Saved file 448_30603.log locally to the 'fail' folder
2016-06-10 00:34:31,811 WARNING Skipping File 448_30603.log
2016-06-10 00:34:32,211 INFO Successfully downloaded file from URL https://logs1.incapsula.com/448_290059/448_30604.log
2016-06-10 00:34:32,365 INFO Saving file 448_30604.log locally to the 'fail' folder global name 'today' is not defined Traceback (most recent call last):
  File "LogsDownloader.py", line 198, in handle_file
    self.handle_log_decrypted_content(logfile, decrypted_file)
  File "LogsDownloader.py", line 242, in handle_log_decrypted_content
    local_file_nf = today.strftime(self.config.PROCESS_DIR + '%Y%m%d%H%M.log')
NameError: global name 'today' is not defined

2016-06-10 00:34:32,382 INFO Saved file 448_30604.log locally to the 'fail' folder
2016-06-10 00:34:32,388 WARNING Skipping File 448_30604.log
2016-06-10 00:34:32,767 INFO Successfully downloaded file from URL https://logs1.incapsula.com/448_290059/448_30605.log
2016-06-10 00:34:32,956 INFO Saving file 448_30605.log locally to the 'fail' folder global name 'today' is not defined Traceback (most recent call last):
  File "LogsDownloader.py", line 198, in handle_file
    self.handle_log_decrypted_content(logfile, decrypted_file)
  File "LogsDownloader.py", line 242, in handle_log_decrypted_content
    local_file_nf = today.strftime(self.config.PROCESS_DIR + '%Y%m%d%H%M.log')
NameError: global name 'today' is not defined

2016-06-10 00:34:32,970 INFO Saved file 448_30605.log locally to the 'fail' folder
2016-06-10 00:34:32,973 WARNING Skipping File 448_30605.log
2016-06-10 00:34:33,403 INFO Successfully downloaded file from URL https://logs1.incapsula.com/448_290059/448_30606.log
2016-06-10 00:34:33,430 INFO Saving file 448_30606.log locally to the 'fail' folder global name 'today' is not defined Traceback (most recent call last):
  File "LogsDownloader.py", line 198, in handle_file
    self.handle_log_decrypted_content(logfile, decrypted_file)
  File "LogsDownloader.py", line 242, in handle_log_decrypted_content
    local_file_nf = today.strftime(self.config.PROCESS_DIR + '%Y%m%d%H%M.log')
NameError: global name 'today' is not defined

2016-06-10 00:34:33,467 INFO Saved file 448_30606.log locally to the 'fail' folder
2016-06-10 00:34:33,473 WARNING Skipping File 448_30606.log
2016-06-10 00:34:34,177 INFO Successfully downloaded file from URL https://logs1.incapsula.com/448_290059/448_30607.log
2016-06-10 00:34:34,236 INFO Saving file 448_30607.log locally to the 'fail' folder global name 'today' is not defined Traceback (most recent call last):
  File "LogsDownloader.py", line 198, in handle_file
    self.handle_log_decrypted_content(logfile, decrypted_file)
  File "LogsDownloader.py", line 242, in handle_log_decrypted_content
    local_file_nf = today.strftime(self.config.PROCESS_DIR + '%Y%m%d%H%M.log')
NameError: global name 'today' is not defined

2016-06-10 00:34:34,326 INFO Saved file 448_30607.log locally to the 'fail' folder
2016-06-10 00:34:34,335 WARNING Skipping File 448_30607.log
2016-06-10 00:34:34,832 INFO Successfully downloaded file from URL https://logs1.incapsula.com/448_290059/448_30608.log
2016-06-10 00:34:35,540 INFO Saving file 448_30608.log locally to the 'fail' folder global name 'today' is not defined Traceback (most recent call last):
  File "LogsDownloader.py", line 198, in handle_file
    self.handle_log_decrypted_content(logfile, decrypted_file)
  File "LogsDownloader.py", line 242, in handle_log_decrypted_content
    local_file_nf = today.strftime(self.config.PROCESS_DIR + '%Y%m%d%H%M.log')
NameError: global name 'today' is not defined

2016-06-10 00:34:35,558 INFO Saved file 448_30608.log locally to the 'fail' folder
2016-06-10 00:34:36,138 WARNING Skipping File 448_30608.log
2016-06-10 00:34:36,812 INFO Successfully downloaded file from URL https://logs1.incapsula.com/448_290059/448_30609.log
2016-06-10 00:34:37,956 INFO Saving file 448_30609.log locally to the 'fail' folder global name 'today' is not defined Traceback (most recent call last):
  File "LogsDownloader.py", line 198, in handle_file
    self.handle_log_decrypted_content(logfile, decrypted_file)
  File "LogsDownloader.py", line 242, in handle_log_decrypted_content
    local_file_nf = today.strftime(self.config.PROCESS_DIR + '%Y%m%d%H%M.log')
NameError: global name 'today' is not defined

2016-06-10 00:34:37,982 INFO Saved file 448_30609.log locally to the 'fail' folder
2016-06-10 00:34:37,992 WARNING Skipping File 448_30609.log
2016-06-10 00:38:45,612 DEBUG Initializing LogsDownloader
2016-06-10 00:38:45,618 INFO LogsDownloader initializing is done
2016-06-10 00:38:45,621 INFO No last downloaded file is found - downloading index file and starting to download all the log files in it
2016-06-10 00:38:45,624 INFO Downloading logs index file...
2016-06-10 00:38:46,548 INFO Successfully downloaded file from URL https://logs1.incapsula.com/448_290059/logs.index
2016-06-10 00:38:46,703 INFO No last index found, will now scan the entire index...
2016-06-10 00:38:47,135 INFO Successfully downloaded file from URL https://logs1.incapsula.com/448_290059/448_30587.log
2016-06-10 00:38:47,229 INFO Saving file 448_30587.log locally to the 'fail' folder must be string, not file Traceback (most recent call last):
  File "LogsDownloader.py", line 198, in handle_file
    self.handle_log_decrypted_content(logfile, decrypted_file)
  File "LogsDownloader.py", line 243, in handle_log_decrypted_content
    shutil.move(local_file, local_file_nf)
  File "C:\Python27\lib\shutil.py", line 294, in move
    os.rename(src, real_dst)
TypeError: must be string, not file

2016-06-10 00:38:47,259 INFO Saved file 448_30587.log locally to the 'fail' folder
2016-06-10 00:38:47,269 WARNING Skipping File 448_30587.log
2016-06-10 00:38:47,723 INFO Successfully downloaded file from URL https://logs1.incapsula.com/448_290059/448_30588.log
2016-06-10 00:38:47,816 INFO Saving file 448_30588.log locally to the 'fail' folder must be string, not file Traceback (most recent call last):
  File "LogsDownloader.py", line 198, in handle_file
    self.handle_log_decrypted_content(logfile, decrypted_file)
  File "LogsDownloader.py", line 243, in handle_log_decrypted_content
    shutil.move(local_file, local_file_nf)
  File "C:\Python27\lib\shutil.py", line 294, in move
    os.rename(src, real_dst)
TypeError: must be string, not file

2016-06-10 00:38:47,826 INFO Saved file 448_30588.log locally to the 'fail' folder
2016-06-10 00:38:47,831 WARNING Skipping File 448_30588.log
2016-06-10 00:38:48,214 INFO Successfully downloaded file from URL https://logs1.incapsula.com/448_290059/448_30589.log
2016-06-10 00:38:48,288 INFO Saving file 448_30589.log locally to the 'fail' folder must be string, not file Traceback (most recent call last):
  File "LogsDownloader.py", line 198, in handle_file
    self.handle_log_decrypted_content(logfile, decrypted_file)
  File "LogsDownloader.py", line 243, in handle_log_decrypted_content
    shutil.move(local_file, local_file_nf)
  File "C:\Python27\lib\shutil.py", line 294, in move
    os.rename(src, real_dst)
TypeError: must be string, not file

2016-06-10 00:38:48,301 INFO Saved file 448_30589.log locally to the 'fail' folder
2016-06-10 00:38:48,305 WARNING Skipping File 448_30589.log
2016-06-10 00:38:48,711 INFO Successfully downloaded file from URL https://logs1.incapsula.com/448_290059/448_30590.log
2016-06-10 00:38:48,792 INFO Saving file 448_30590.log locally to the 'fail' folder must be string, not file Traceback (most recent call last):
  File "LogsDownloader.py", line 198, in handle_file
    self.handle_log_decrypted_content(logfile, decrypted_file)
  File "LogsDownloader.py", line 243, in handle_log_decrypted_content
    shutil.move(local_file, local_file_nf)
  File "C:\Python27\lib\shutil.py", line 294, in move
    os.rename(src, real_dst)
TypeError: must be string, not file

2016-06-10 00:38:48,813 INFO Saved file 448_30590.log locally to the 'fail' folder
2016-06-10 00:38:48,831 WARNING Skipping File 448_30590.log
2016-06-10 00:38:49,247 INFO Successfully downloaded file from URL https://logs1.incapsula.com/448_290059/448_30591.log
2016-06-10 00:38:49,336 INFO Saving file 448_30591.log locally to the 'fail' folder must be string, not file Traceback (most recent call last):
  File "LogsDownloader.py", line 198, in handle_file
    self.handle_log_decrypted_content(logfile, decrypted_file)
  File "LogsDownloader.py", line 243, in handle_log_decrypted_content
    shutil.move(local_file, local_file_nf)
  File "C:\Python27\lib\shutil.py", line 294, in move
    os.rename(src, real_dst)
TypeError: must be string, not file

2016-06-10 00:38:49,348 INFO Saved file 448_30591.log locally to the 'fail' folder
2016-06-10 00:38:49,352 WARNING Skipping File 448_30591.log
2016-06-10 00:38:49,846 INFO Successfully downloaded file from URL https://logs1.incapsula.com/448_290059/448_30592.log
2016-06-10 00:38:49,917 INFO Saving file 448_30592.log locally to the 'fail' folder must be string, not file Traceback (most recent call last):
  File "LogsDownloader.py", line 198, in handle_file
    self.handle_log_decrypted_content(logfile, decrypted_file)
  File "LogsDownloader.py", line 243, in handle_log_decrypted_content
    shutil.move(local_file, local_file_nf)
  File "C:\Python27\lib\shutil.py", line 294, in move
    os.rename(src, real_dst)
TypeError: must be string, not file

2016-06-10 00:38:49,934 INFO Saved file 448_30592.log locally to the 'fail' folder
2016-06-10 00:38:49,937 WARNING Skipping File 448_30592.log
2016-06-10 00:38:50,375 INFO Successfully downloaded file from URL https://logs1.incapsula.com/448_290059/448_30593.log
2016-06-10 00:38:50,526 INFO Saving file 448_30593.log locally to the 'fail' folder must be string, not file Traceback (most recent call last):
  File "LogsDownloader.py", line 198, in handle_file
    self.handle_log_decrypted_content(logfile, decrypted_file)
  File "LogsDownloader.py", line 243, in handle_log_decrypted_content
    shutil.move(local_file, local_file_nf)
  File "C:\Python27\lib\shutil.py", line 294, in move
    os.rename(src, real_dst)
TypeError: must be string, not file

2016-06-10 00:38:50,546 INFO Saved file 448_30593.log locally to the 'fail' folder
2016-06-10 00:38:50,551 WARNING Skipping File 448_30593.log
2016-06-10 00:38:50,990 INFO Successfully downloaded file from URL https://logs1.incapsula.com/448_290059/448_30594.log
2016-06-10 00:38:51,095 INFO Saving file 448_30594.log locally to the 'fail' folder must be string, not file Traceback (most recent call last):
  File "LogsDownloader.py", line 198, in handle_file
    self.handle_log_decrypted_content(logfile, decrypted_file)
  File "LogsDownloader.py", line 243, in handle_log_decrypted_content
    shutil.move(local_file, local_file_nf)
  File "C:\Python27\lib\shutil.py", line 294, in move
    os.rename(src, real_dst)
TypeError: must be string, not file

2016-06-10 00:38:51,111 INFO Saved file 448_30594.log locally to the 'fail' folder
2016-06-10 00:38:51,115 WARNING Skipping File 448_30594.log
2016-06-10 00:38:51,555 INFO Successfully downloaded file from URL https://logs1.incapsula.com/448_290059/448_30595.log
2016-06-10 00:38:51,657 INFO Saving file 448_30595.log locally to the 'fail' folder must be string, not file Traceback (most recent call last):
  File "LogsDownloader.py", line 198, in handle_file
    self.handle_log_decrypted_content(logfile, decrypted_file)
  File "LogsDownloader.py", line 243, in handle_log_decrypted_content
    shutil.move(local_file, local_file_nf)
  File "C:\Python27\lib\shutil.py", line 294, in move
    os.rename(src, real_dst)
TypeError: must be string, not file

2016-06-10 00:38:51,678 INFO Saved file 448_30595.log locally to the 'fail' folder
2016-06-10 00:38:51,683 WARNING Skipping File 448_30595.log
2016-06-10 00:38:52,105 INFO Successfully downloaded file from URL https://logs1.incapsula.com/448_290059/448_30596.log
2016-06-10 00:38:52,196 INFO Saving file 448_30596.log locally to the 'fail' folder must be string, not file Traceback (most recent call last):
  File "LogsDownloader.py", line 198, in handle_file
    self.handle_log_decrypted_content(logfile, decrypted_file)
  File "LogsDownloader.py", line 243, in handle_log_decrypted_content
    shutil.move(local_file, local_file_nf)
  File "C:\Python27\lib\shutil.py", line 294, in move
    os.rename(src, real_dst)
TypeError: must be string, not file

2016-06-10 00:38:52,211 INFO Saved file 448_30596.log locally to the 'fail' folder
2016-06-10 00:38:52,213 WARNING Skipping File 448_30596.log
2016-06-10 00:38:52,668 INFO Successfully downloaded file from URL https://logs1.incapsula.com/448_290059/448_30597.log
2016-06-10 00:38:52,779 INFO Saving file 448_30597.log locally to the 'fail' folder must be string, not file Traceback (most recent call last):
  File "LogsDownloader.py", line 198, in handle_file
    self.handle_log_decrypted_content(logfile, decrypted_file)
  File "LogsDownloader.py", line 243, in handle_log_decrypted_content
    shutil.move(local_file, local_file_nf)
  File "C:\Python27\lib\shutil.py", line 294, in move
    os.rename(src, real_dst)
TypeError: must be string, not file

2016-06-10 00:38:52,792 INFO Saved file 448_30597.log locally to the 'fail' folder
2016-06-10 00:38:52,796 WARNING Skipping File 448_30597.log
2016-06-10 00:38:53,292 INFO Successfully downloaded file from URL https://logs1.incapsula.com/448_290059/448_30598.log
2016-06-10 00:38:53,400 INFO Saving file 448_30598.log locally to the 'fail' folder must be string, not file Traceback (most recent call last):
  File "LogsDownloader.py", line 198, in handle_file
    self.handle_log_decrypted_content(logfile, decrypted_file)
  File "LogsDownloader.py", line 243, in handle_log_decrypted_content
    shutil.move(local_file, local_file_nf)
  File "C:\Python27\lib\shutil.py", line 294, in move
    os.rename(src, real_dst)
TypeError: must be string, not file

2016-06-10 00:38:53,415 INFO Saved file 448_30598.log locally to the 'fail' folder
2016-06-10 00:38:53,420 WARNING Skipping File 448_30598.log
2016-06-10 00:38:53,806 INFO Successfully downloaded file from URL https://logs1.incapsula.com/448_290059/448_30599.log
2016-06-10 00:38:53,826 INFO Saving file 448_30599.log locally to the 'fail' folder must be string, not file Traceback (most recent call last):
  File "LogsDownloader.py", line 198, in handle_file
    self.handle_log_decrypted_content(logfile, decrypted_file)
  File "LogsDownloader.py", line 243, in handle_log_decrypted_content
    shutil.move(local_file, local_file_nf)
  File "C:\Python27\lib\shutil.py", line 294, in move
    os.rename(src, real_dst)
TypeError: must be string, not file

2016-06-10 00:38:53,844 INFO Saved file 448_30599.log locally to the 'fail' folder
2016-06-10 00:38:53,848 WARNING Skipping File 448_30599.log
2016-06-10 00:38:54,358 INFO Successfully downloaded file from URL https://logs1.incapsula.com/448_290059/448_30600.log
2016-06-10 00:38:54,453 INFO Saving file 448_30600.log locally to the 'fail' folder must be string, not file Traceback (most recent call last):
  File "LogsDownloader.py", line 198, in handle_file
    self.handle_log_decrypted_content(logfile, decrypted_file)
  File "LogsDownloader.py", line 243, in handle_log_decrypted_content
    shutil.move(local_file, local_file_nf)
  File "C:\Python27\lib\shutil.py", line 294, in move
    os.rename(src, real_dst)
TypeError: must be string, not file

2016-06-10 00:38:54,473 INFO Saved file 448_30600.log locally to the 'fail' folder
2016-06-10 00:38:54,476 WARNING Skipping File 448_30600.log
2016-06-10 00:38:54,898 INFO Successfully downloaded file from URL https://logs1.incapsula.com/448_290059/448_30601.log
2016-06-10 00:38:54,990 INFO Saving file 448_30601.log locally to the 'fail' folder must be string, not file Traceback (most recent call last):
  File "LogsDownloader.py", line 198, in handle_file
    self.handle_log_decrypted_content(logfile, decrypted_file)
  File "LogsDownloader.py", line 243, in handle_log_decrypted_content
    shutil.move(local_file, local_file_nf)
  File "C:\Python27\lib\shutil.py", line 294, in move
    os.rename(src, real_dst)
TypeError: must be string, not file

2016-06-10 00:38:55,003 INFO Saved file 448_30601.log locally to the 'fail' folder
2016-06-10 00:38:55,010 WARNING Skipping File 448_30601.log
2016-06-10 00:38:55,484 INFO Successfully downloaded file from URL https://logs1.incapsula.com/448_290059/448_30602.log
2016-06-10 00:38:55,595 INFO Saving file 448_30602.log locally to the 'fail' folder must be string, not file Traceback (most recent call last):
  File "LogsDownloader.py", line 198, in handle_file
    self.handle_log_decrypted_content(logfile, decrypted_file)
  File "LogsDownloader.py", line 243, in handle_log_decrypted_content
    shutil.move(local_file, local_file_nf)
  File "C:\Python27\lib\shutil.py", line 294, in move
    os.rename(src, real_dst)
TypeError: must be string, not file

2016-06-10 00:38:55,615 INFO Saved file 448_30602.log locally to the 'fail' folder
2016-06-10 00:38:55,621 WARNING Skipping File 448_30602.log
2016-06-10 00:38:55,990 INFO Successfully downloaded file from URL https://logs1.incapsula.com/448_290059/448_30603.log
2016-06-10 00:38:56,101 INFO Saving file 448_30603.log locally to the 'fail' folder must be string, not file Traceback (most recent call last):
  File "LogsDownloader.py", line 198, in handle_file
    self.handle_log_decrypted_content(logfile, decrypted_file)
  File "LogsDownloader.py", line 243, in handle_log_decrypted_content
    shutil.move(local_file, local_file_nf)
  File "C:\Python27\lib\shutil.py", line 294, in move
    os.rename(src, real_dst)
TypeError: must be string, not file

2016-06-10 00:38:56,114 INFO Saved file 448_30603.log locally to the 'fail' folder
2016-06-10 00:38:56,118 WARNING Skipping File 448_30603.log
2016-06-10 00:38:56,651 INFO Successfully downloaded file from URL https://logs1.incapsula.com/448_290059/448_30604.log
2016-06-10 00:38:56,760 INFO Saving file 448_30604.log locally to the 'fail' folder must be string, not file Traceback (most recent call last):
  File "LogsDownloader.py", line 198, in handle_file
    self.handle_log_decrypted_content(logfile, decrypted_file)
  File "LogsDownloader.py", line 243, in handle_log_decrypted_content
    shutil.move(local_file, local_file_nf)
  File "C:\Python27\lib\shutil.py", line 294, in move
    os.rename(src, real_dst)
TypeError: must be string, not file

2016-06-10 00:38:56,773 INFO Saved file 448_30604.log locally to the 'fail' folder
2016-06-10 00:38:56,776 WARNING Skipping File 448_30604.log
2016-06-10 00:43:11,694 DEBUG Initializing LogsDownloader
2016-06-10 00:43:11,697 INFO LogsDownloader initializing is done
2016-06-10 00:43:11,701 INFO No last downloaded file is found - downloading index file and starting to download all the log files in it
2016-06-10 00:43:11,706 INFO Downloading logs index file...
2016-06-10 00:43:13,276 INFO Successfully downloaded file from URL https://logs1.incapsula.com/448_290059/logs.index
2016-06-10 00:43:13,464 INFO No last index found, will now scan the entire index...
2016-06-10 00:43:14,020 INFO Successfully downloaded file from URL https://logs1.incapsula.com/448_290059/448_30587.log
2016-06-10 00:43:14,122 INFO Saving file 448_30587.log locally to the 'fail' folder  Traceback (most recent call last):
  File "LogsDownloader.py", line 198, in handle_file
    self.handle_log_decrypted_content(logfile, decrypted_file)
  File "LogsDownloader.py", line 244, in handle_log_decrypted_content
    shutil.move(local_file_of, local_file_nf)
  File "C:\Python27\lib\shutil.py", line 303, in move
    os.unlink(src)
WindowsError: [Error 32] The process cannot access the file because it is being used by another process: u'C:\\\\Users\\\\lester.john\\\\Documents\\\\NetBeansProjects\\\\logs-downloader\\\\config\\448_30587.log'

2016-06-10 00:43:14,144 INFO Saved file 448_30587.log locally to the 'fail' folder
2016-06-10 00:43:14,151 WARNING Skipping File 448_30587.log
2016-06-10 00:43:14,618 INFO Successfully downloaded file from URL https://logs1.incapsula.com/448_290059/448_30588.log
2016-06-10 00:43:14,747 INFO Saving file 448_30588.log locally to the 'fail' folder  Traceback (most recent call last):
  File "LogsDownloader.py", line 198, in handle_file
    self.handle_log_decrypted_content(logfile, decrypted_file)
  File "LogsDownloader.py", line 244, in handle_log_decrypted_content
    shutil.move(local_file_of, local_file_nf)
  File "C:\Python27\lib\shutil.py", line 303, in move
    os.unlink(src)
WindowsError: [Error 32] The process cannot access the file because it is being used by another process: u'C:\\\\Users\\\\lester.john\\\\Documents\\\\NetBeansProjects\\\\logs-downloader\\\\config\\448_30588.log'

2016-06-10 00:43:14,766 INFO Saved file 448_30588.log locally to the 'fail' folder
2016-06-10 00:43:14,769 WARNING Skipping File 448_30588.log
2016-06-10 00:43:15,232 INFO Successfully downloaded file from URL https://logs1.incapsula.com/448_290059/448_30589.log
2016-06-10 00:43:15,355 INFO Saving file 448_30589.log locally to the 'fail' folder  Traceback (most recent call last):
  File "LogsDownloader.py", line 198, in handle_file
    self.handle_log_decrypted_content(logfile, decrypted_file)
  File "LogsDownloader.py", line 244, in handle_log_decrypted_content
    shutil.move(local_file_of, local_file_nf)
  File "C:\Python27\lib\shutil.py", line 303, in move
    os.unlink(src)
WindowsError: [Error 32] The process cannot access the file because it is being used by another process: u'C:\\\\Users\\\\lester.john\\\\Documents\\\\NetBeansProjects\\\\logs-downloader\\\\config\\448_30589.log'

2016-06-10 00:43:15,369 INFO Saved file 448_30589.log locally to the 'fail' folder
2016-06-10 00:43:15,374 WARNING Skipping File 448_30589.log
2016-06-10 00:43:15,851 INFO Successfully downloaded file from URL https://logs1.incapsula.com/448_290059/448_30590.log
2016-06-10 00:43:15,953 INFO Saving file 448_30590.log locally to the 'fail' folder  Traceback (most recent call last):
  File "LogsDownloader.py", line 198, in handle_file
    self.handle_log_decrypted_content(logfile, decrypted_file)
  File "LogsDownloader.py", line 244, in handle_log_decrypted_content
    shutil.move(local_file_of, local_file_nf)
  File "C:\Python27\lib\shutil.py", line 303, in move
    os.unlink(src)
WindowsError: [Error 32] The process cannot access the file because it is being used by another process: u'C:\\\\Users\\\\lester.john\\\\Documents\\\\NetBeansProjects\\\\logs-downloader\\\\config\\448_30590.log'

2016-06-10 00:43:15,970 INFO Saved file 448_30590.log locally to the 'fail' folder
2016-06-10 00:43:15,976 WARNING Skipping File 448_30590.log
2016-06-10 00:43:16,937 INFO Successfully downloaded file from URL https://logs1.incapsula.com/448_290059/448_30591.log
2016-06-10 00:43:17,055 INFO Saving file 448_30591.log locally to the 'fail' folder  Traceback (most recent call last):
  File "LogsDownloader.py", line 198, in handle_file
    self.handle_log_decrypted_content(logfile, decrypted_file)
  File "LogsDownloader.py", line 244, in handle_log_decrypted_content
    shutil.move(local_file_of, local_file_nf)
  File "C:\Python27\lib\shutil.py", line 303, in move
    os.unlink(src)
WindowsError: [Error 32] The process cannot access the file because it is being used by another process: u'C:\\\\Users\\\\lester.john\\\\Documents\\\\NetBeansProjects\\\\logs-downloader\\\\config\\448_30591.log'

2016-06-10 00:43:17,069 INFO Saved file 448_30591.log locally to the 'fail' folder
2016-06-10 00:43:17,075 WARNING Skipping File 448_30591.log
2016-06-10 00:43:17,680 INFO Successfully downloaded file from URL https://logs1.incapsula.com/448_290059/448_30592.log
2016-06-10 00:43:17,755 INFO Saving file 448_30592.log locally to the 'fail' folder  Traceback (most recent call last):
  File "LogsDownloader.py", line 198, in handle_file
    self.handle_log_decrypted_content(logfile, decrypted_file)
  File "LogsDownloader.py", line 244, in handle_log_decrypted_content
    shutil.move(local_file_of, local_file_nf)
  File "C:\Python27\lib\shutil.py", line 303, in move
    os.unlink(src)
WindowsError: [Error 32] The process cannot access the file because it is being used by another process: u'C:\\\\Users\\\\lester.john\\\\Documents\\\\NetBeansProjects\\\\logs-downloader\\\\config\\448_30592.log'

2016-06-10 00:43:17,769 INFO Saved file 448_30592.log locally to the 'fail' folder
2016-06-10 00:43:17,773 WARNING Skipping File 448_30592.log
2016-06-10 00:43:18,250 INFO Successfully downloaded file from URL https://logs1.incapsula.com/448_290059/448_30593.log
2016-06-10 00:43:18,410 INFO Saving file 448_30593.log locally to the 'fail' folder  Traceback (most recent call last):
  File "LogsDownloader.py", line 198, in handle_file
    self.handle_log_decrypted_content(logfile, decrypted_file)
  File "LogsDownloader.py", line 244, in handle_log_decrypted_content
    shutil.move(local_file_of, local_file_nf)
  File "C:\Python27\lib\shutil.py", line 303, in move
    os.unlink(src)
WindowsError: [Error 32] The process cannot access the file because it is being used by another process: u'C:\\\\Users\\\\lester.john\\\\Documents\\\\NetBeansProjects\\\\logs-downloader\\\\config\\448_30593.log'

2016-06-10 00:43:18,426 INFO Saved file 448_30593.log locally to the 'fail' folder
2016-06-10 00:43:18,427 WARNING Skipping File 448_30593.log
2016-06-10 00:43:18,845 INFO Successfully downloaded file from URL https://logs1.incapsula.com/448_290059/448_30594.log
2016-06-10 00:43:18,944 INFO Saving file 448_30594.log locally to the 'fail' folder  Traceback (most recent call last):
  File "LogsDownloader.py", line 198, in handle_file
    self.handle_log_decrypted_content(logfile, decrypted_file)
  File "LogsDownloader.py", line 244, in handle_log_decrypted_content
    shutil.move(local_file_of, local_file_nf)
  File "C:\Python27\lib\shutil.py", line 303, in move
    os.unlink(src)
WindowsError: [Error 32] The process cannot access the file because it is being used by another process: u'C:\\\\Users\\\\lester.john\\\\Documents\\\\NetBeansProjects\\\\logs-downloader\\\\config\\448_30594.log'

2016-06-10 00:43:18,960 INFO Saved file 448_30594.log locally to the 'fail' folder
2016-06-10 00:43:18,964 WARNING Skipping File 448_30594.log
2016-06-10 00:43:19,453 INFO Successfully downloaded file from URL https://logs1.incapsula.com/448_290059/448_30595.log
2016-06-10 00:43:19,551 INFO Saving file 448_30595.log locally to the 'fail' folder  Traceback (most recent call last):
  File "LogsDownloader.py", line 198, in handle_file
    self.handle_log_decrypted_content(logfile, decrypted_file)
  File "LogsDownloader.py", line 244, in handle_log_decrypted_content
    shutil.move(local_file_of, local_file_nf)
  File "C:\Python27\lib\shutil.py", line 303, in move
    os.unlink(src)
WindowsError: [Error 32] The process cannot access the file because it is being used by another process: u'C:\\\\Users\\\\lester.john\\\\Documents\\\\NetBeansProjects\\\\logs-downloader\\\\config\\448_30595.log'

2016-06-10 00:43:19,568 INFO Saved file 448_30595.log locally to the 'fail' folder
2016-06-10 00:43:19,571 WARNING Skipping File 448_30595.log
2016-06-10 00:43:20,032 INFO Successfully downloaded file from URL https://logs1.incapsula.com/448_290059/448_30596.log
2016-06-10 00:43:20,157 INFO Saving file 448_30596.log locally to the 'fail' folder  Traceback (most recent call last):
  File "LogsDownloader.py", line 198, in handle_file
    self.handle_log_decrypted_content(logfile, decrypted_file)
  File "LogsDownloader.py", line 244, in handle_log_decrypted_content
    shutil.move(local_file_of, local_file_nf)
  File "C:\Python27\lib\shutil.py", line 303, in move
    os.unlink(src)
WindowsError: [Error 32] The process cannot access the file because it is being used by another process: u'C:\\\\Users\\\\lester.john\\\\Documents\\\\NetBeansProjects\\\\logs-downloader\\\\config\\448_30596.log'

2016-06-10 00:43:20,176 INFO Saved file 448_30596.log locally to the 'fail' folder
2016-06-10 00:43:20,178 WARNING Skipping File 448_30596.log
2016-06-10 00:43:20,588 INFO Successfully downloaded file from URL https://logs1.incapsula.com/448_290059/448_30597.log
2016-06-10 00:43:20,687 INFO Saving file 448_30597.log locally to the 'fail' folder  Traceback (most recent call last):
  File "LogsDownloader.py", line 198, in handle_file
    self.handle_log_decrypted_content(logfile, decrypted_file)
  File "LogsDownloader.py", line 244, in handle_log_decrypted_content
    shutil.move(local_file_of, local_file_nf)
  File "C:\Python27\lib\shutil.py", line 303, in move
    os.unlink(src)
WindowsError: [Error 32] The process cannot access the file because it is being used by another process: u'C:\\\\Users\\\\lester.john\\\\Documents\\\\NetBeansProjects\\\\logs-downloader\\\\config\\448_30597.log'

2016-06-10 00:43:20,704 INFO Saved file 448_30597.log locally to the 'fail' folder
2016-06-10 00:43:20,711 WARNING Skipping File 448_30597.log
2016-06-10 00:43:21,157 INFO Successfully downloaded file from URL https://logs1.incapsula.com/448_290059/448_30598.log
2016-06-10 00:43:21,249 INFO Saving file 448_30598.log locally to the 'fail' folder  Traceback (most recent call last):
  File "LogsDownloader.py", line 198, in handle_file
    self.handle_log_decrypted_content(logfile, decrypted_file)
  File "LogsDownloader.py", line 244, in handle_log_decrypted_content
    shutil.move(local_file_of, local_file_nf)
  File "C:\Python27\lib\shutil.py", line 303, in move
    os.unlink(src)
WindowsError: [Error 32] The process cannot access the file because it is being used by another process: u'C:\\\\Users\\\\lester.john\\\\Documents\\\\NetBeansProjects\\\\logs-downloader\\\\config\\448_30598.log'

2016-06-10 00:43:21,273 INFO Saved file 448_30598.log locally to the 'fail' folder
2016-06-10 00:43:21,276 WARNING Skipping File 448_30598.log
2016-06-10 00:43:21,648 INFO Successfully downloaded file from URL https://logs1.incapsula.com/448_290059/448_30599.log
2016-06-10 00:43:21,670 INFO Saving file 448_30599.log locally to the 'fail' folder  Traceback (most recent call last):
  File "LogsDownloader.py", line 198, in handle_file
    self.handle_log_decrypted_content(logfile, decrypted_file)
  File "LogsDownloader.py", line 244, in handle_log_decrypted_content
    shutil.move(local_file_of, local_file_nf)
  File "C:\Python27\lib\shutil.py", line 303, in move
    os.unlink(src)
WindowsError: [Error 32] The process cannot access the file because it is being used by another process: u'C:\\\\Users\\\\lester.john\\\\Documents\\\\NetBeansProjects\\\\logs-downloader\\\\config\\448_30599.log'

2016-06-10 00:43:21,681 INFO Saved file 448_30599.log locally to the 'fail' folder
2016-06-10 00:43:21,684 WARNING Skipping File 448_30599.log
2016-06-10 00:43:22,134 INFO Successfully downloaded file from URL https://logs1.incapsula.com/448_290059/448_30600.log
2016-06-10 00:43:22,269 INFO Saving file 448_30600.log locally to the 'fail' folder  Traceback (most recent call last):
  File "LogsDownloader.py", line 198, in handle_file
    self.handle_log_decrypted_content(logfile, decrypted_file)
  File "LogsDownloader.py", line 244, in handle_log_decrypted_content
    shutil.move(local_file_of, local_file_nf)
  File "C:\Python27\lib\shutil.py", line 303, in move
    os.unlink(src)
WindowsError: [Error 32] The process cannot access the file because it is being used by another process: u'C:\\\\Users\\\\lester.john\\\\Documents\\\\NetBeansProjects\\\\logs-downloader\\\\config\\448_30600.log'

2016-06-10 00:43:22,282 INFO Saved file 448_30600.log locally to the 'fail' folder
2016-06-10 00:43:22,286 WARNING Skipping File 448_30600.log
2016-06-10 00:43:22,730 INFO Successfully downloaded file from URL https://logs1.incapsula.com/448_290059/448_30601.log
2016-06-10 00:43:22,832 INFO Saving file 448_30601.log locally to the 'fail' folder  Traceback (most recent call last):
  File "LogsDownloader.py", line 198, in handle_file
    self.handle_log_decrypted_content(logfile, decrypted_file)
  File "LogsDownloader.py", line 244, in handle_log_decrypted_content
    shutil.move(local_file_of, local_file_nf)
  File "C:\Python27\lib\shutil.py", line 303, in move
    os.unlink(src)
WindowsError: [Error 32] The process cannot access the file because it is being used by another process: u'C:\\\\Users\\\\lester.john\\\\Documents\\\\NetBeansProjects\\\\logs-downloader\\\\config\\448_30601.log'

2016-06-10 00:43:22,846 INFO Saved file 448_30601.log locally to the 'fail' folder
2016-06-10 00:43:22,848 WARNING Skipping File 448_30601.log
2016-06-10 00:43:23,292 INFO Successfully downloaded file from URL https://logs1.incapsula.com/448_290059/448_30602.log
2016-06-10 00:43:23,414 INFO Saving file 448_30602.log locally to the 'fail' folder  Traceback (most recent call last):
  File "LogsDownloader.py", line 198, in handle_file
    self.handle_log_decrypted_content(logfile, decrypted_file)
  File "LogsDownloader.py", line 244, in handle_log_decrypted_content
    shutil.move(local_file_of, local_file_nf)
  File "C:\Python27\lib\shutil.py", line 303, in move
    os.unlink(src)
WindowsError: [Error 32] The process cannot access the file because it is being used by another process: u'C:\\\\Users\\\\lester.john\\\\Documents\\\\NetBeansProjects\\\\logs-downloader\\\\config\\448_30602.log'

2016-06-10 00:43:23,433 INFO Saved file 448_30602.log locally to the 'fail' folder
2016-06-10 00:43:23,437 WARNING Skipping File 448_30602.log
2016-06-10 00:43:23,844 INFO Successfully downloaded file from URL https://logs1.incapsula.com/448_290059/448_30603.log
2016-06-10 00:43:24,023 INFO Saving file 448_30603.log locally to the 'fail' folder  Traceback (most recent call last):
  File "LogsDownloader.py", line 198, in handle_file
    self.handle_log_decrypted_content(logfile, decrypted_file)
  File "LogsDownloader.py", line 244, in handle_log_decrypted_content
    shutil.move(local_file_of, local_file_nf)
  File "C:\Python27\lib\shutil.py", line 303, in move
    os.unlink(src)
WindowsError: [Error 32] The process cannot access the file because it is being used by another process: u'C:\\\\Users\\\\lester.john\\\\Documents\\\\NetBeansProjects\\\\logs-downloader\\\\config\\448_30603.log'

2016-06-10 00:43:24,042 INFO Saved file 448_30603.log locally to the 'fail' folder
2016-06-10 00:43:24,046 WARNING Skipping File 448_30603.log
2016-06-10 00:43:24,483 INFO Successfully downloaded file from URL https://logs1.incapsula.com/448_290059/448_30604.log
2016-06-10 00:43:24,663 INFO Saving file 448_30604.log locally to the 'fail' folder  Traceback (most recent call last):
  File "LogsDownloader.py", line 198, in handle_file
    self.handle_log_decrypted_content(logfile, decrypted_file)
  File "LogsDownloader.py", line 244, in handle_log_decrypted_content
    shutil.move(local_file_of, local_file_nf)
  File "C:\Python27\lib\shutil.py", line 303, in move
    os.unlink(src)
WindowsError: [Error 32] The process cannot access the file because it is being used by another process: u'C:\\\\Users\\\\lester.john\\\\Documents\\\\NetBeansProjects\\\\logs-downloader\\\\config\\448_30604.log'

2016-06-10 00:43:24,690 INFO Saved file 448_30604.log locally to the 'fail' folder
2016-06-10 00:43:24,713 WARNING Skipping File 448_30604.log
2016-06-10 00:43:25,154 INFO Successfully downloaded file from URL https://logs1.incapsula.com/448_290059/448_30605.log
2016-06-10 00:43:25,302 INFO Saving file 448_30605.log locally to the 'fail' folder  Traceback (most recent call last):
  File "LogsDownloader.py", line 198, in handle_file
    self.handle_log_decrypted_content(logfile, decrypted_file)
  File "LogsDownloader.py", line 244, in handle_log_decrypted_content
    shutil.move(local_file_of, local_file_nf)
  File "C:\Python27\lib\shutil.py", line 303, in move
    os.unlink(src)
WindowsError: [Error 32] The process cannot access the file because it is being used by another process: u'C:\\\\Users\\\\lester.john\\\\Documents\\\\NetBeansProjects\\\\logs-downloader\\\\config\\448_30605.log'

2016-06-10 00:43:25,325 INFO Saved file 448_30605.log locally to the 'fail' folder
2016-06-10 00:43:25,331 WARNING Skipping File 448_30605.log
2016-06-10 00:43:25,760 INFO Successfully downloaded file from URL https://logs1.incapsula.com/448_290059/448_30606.log
2016-06-10 00:43:25,798 INFO Saving file 448_30606.log locally to the 'fail' folder  Traceback (most recent call last):
  File "LogsDownloader.py", line 198, in handle_file
    self.handle_log_decrypted_content(logfile, decrypted_file)
  File "LogsDownloader.py", line 244, in handle_log_decrypted_content
    shutil.move(local_file_of, local_file_nf)
  File "C:\Python27\lib\shutil.py", line 303, in move
    os.unlink(src)
WindowsError: [Error 32] The process cannot access the file because it is being used by another process: u'C:\\\\Users\\\\lester.john\\\\Documents\\\\NetBeansProjects\\\\logs-downloader\\\\config\\448_30606.log'

2016-06-10 00:43:25,811 INFO Saved file 448_30606.log locally to the 'fail' folder
2016-06-10 00:43:25,813 WARNING Skipping File 448_30606.log
2016-06-10 00:43:26,290 INFO Successfully downloaded file from URL https://logs1.incapsula.com/448_290059/448_30607.log
2016-06-10 00:43:26,302 INFO Saving file 448_30607.log locally to the 'fail' folder  Traceback (most recent call last):
  File "LogsDownloader.py", line 198, in handle_file
    self.handle_log_decrypted_content(logfile, decrypted_file)
  File "LogsDownloader.py", line 244, in handle_log_decrypted_content
    shutil.move(local_file_of, local_file_nf)
  File "C:\Python27\lib\shutil.py", line 303, in move
    os.unlink(src)
WindowsError: [Error 32] The process cannot access the file because it is being used by another process: u'C:\\\\Users\\\\lester.john\\\\Documents\\\\NetBeansProjects\\\\logs-downloader\\\\config\\448_30607.log'

2016-06-10 00:43:26,325 INFO Saved file 448_30607.log locally to the 'fail' folder
2016-06-10 00:43:26,329 WARNING Skipping File 448_30607.log
2016-06-10 00:43:26,769 INFO Successfully downloaded file from URL https://logs1.incapsula.com/448_290059/448_30608.log
2016-06-10 00:43:26,819 INFO Saving file 448_30608.log locally to the 'fail' folder  Traceback (most recent call last):
  File "LogsDownloader.py", line 198, in handle_file
    self.handle_log_decrypted_content(logfile, decrypted_file)
  File "LogsDownloader.py", line 244, in handle_log_decrypted_content
    shutil.move(local_file_of, local_file_nf)
  File "C:\Python27\lib\shutil.py", line 303, in move
    os.unlink(src)
WindowsError: [Error 32] The process cannot access the file because it is being used by another process: u'C:\\\\Users\\\\lester.john\\\\Documents\\\\NetBeansProjects\\\\logs-downloader\\\\config\\448_30608.log'

2016-06-10 00:43:26,835 INFO Saved file 448_30608.log locally to the 'fail' folder
2016-06-10 00:43:26,839 WARNING Skipping File 448_30608.log
2016-06-10 00:43:27,224 INFO Successfully downloaded file from URL https://logs1.incapsula.com/448_290059/448_30609.log
2016-06-10 00:43:27,329 INFO Saving file 448_30609.log locally to the 'fail' folder  Traceback (most recent call last):
  File "LogsDownloader.py", line 198, in handle_file
    self.handle_log_decrypted_content(logfile, decrypted_file)
  File "LogsDownloader.py", line 244, in handle_log_decrypted_content
    shutil.move(local_file_of, local_file_nf)
  File "C:\Python27\lib\shutil.py", line 303, in move
    os.unlink(src)
WindowsError: [Error 32] The process cannot access the file because it is being used by another process: u'C:\\\\Users\\\\lester.john\\\\Documents\\\\NetBeansProjects\\\\logs-downloader\\\\config\\448_30609.log'

2016-06-10 00:43:27,351 INFO Saved file 448_30609.log locally to the 'fail' folder
2016-06-10 00:43:27,354 WARNING Skipping File 448_30609.log
2016-06-10 00:43:27,782 INFO Successfully downloaded file from URL https://logs1.incapsula.com/448_290059/448_30610.log
2016-06-10 00:43:27,835 INFO Saving file 448_30610.log locally to the 'fail' folder  Traceback (most recent call last):
  File "LogsDownloader.py", line 198, in handle_file
    self.handle_log_decrypted_content(logfile, decrypted_file)
  File "LogsDownloader.py", line 244, in handle_log_decrypted_content
    shutil.move(local_file_of, local_file_nf)
  File "C:\Python27\lib\shutil.py", line 303, in move
    os.unlink(src)
WindowsError: [Error 32] The process cannot access the file because it is being used by another process: u'C:\\\\Users\\\\lester.john\\\\Documents\\\\NetBeansProjects\\\\logs-downloader\\\\config\\448_30610.log'

2016-06-10 00:43:27,849 INFO Saved file 448_30610.log locally to the 'fail' folder
2016-06-10 00:43:27,854 WARNING Skipping File 448_30610.log
2016-06-10 00:43:28,335 INFO Successfully downloaded file from URL https://logs1.incapsula.com/448_290059/448_30611.log
2016-06-10 00:43:28,448 INFO Saving file 448_30611.log locally to the 'fail' folder  Traceback (most recent call last):
  File "LogsDownloader.py", line 198, in handle_file
    self.handle_log_decrypted_content(logfile, decrypted_file)
  File "LogsDownloader.py", line 244, in handle_log_decrypted_content
    shutil.move(local_file_of, local_file_nf)
  File "C:\Python27\lib\shutil.py", line 303, in move
    os.unlink(src)
WindowsError: [Error 32] The process cannot access the file because it is being used by another process: u'C:\\\\Users\\\\lester.john\\\\Documents\\\\NetBeansProjects\\\\logs-downloader\\\\config\\448_30611.log'

2016-06-10 00:43:28,466 INFO Saved file 448_30611.log locally to the 'fail' folder
2016-06-10 00:43:28,470 WARNING Skipping File 448_30611.log
2016-06-10 00:52:48,986 DEBUG Initializing LogsDownloader
2016-06-10 00:52:48,987 INFO LogsDownloader initializing is done
2016-06-10 00:52:48,990 INFO No last downloaded file is found - downloading index file and starting to download all the log files in it
2016-06-10 00:52:48,990 INFO Downloading logs index file...
2016-06-10 00:52:50,007 INFO Successfully downloaded file from URL https://logs1.incapsula.com/448_290059/logs.index
2016-06-10 00:52:50,549 INFO No last index found, will now scan the entire index...
2016-06-10 00:52:51,273 INFO Successfully downloaded file from URL https://logs1.incapsula.com/448_290059/448_30634.log
2016-06-10 00:52:51,372 INFO Saving file 448_30634.log locally to the 'fail' folder  Traceback (most recent call last):
  File "LogsDownloader.py", line 198, in handle_file
    self.handle_log_decrypted_content(logfile, decrypted_file)
  File "LogsDownloader.py", line 244, in handle_log_decrypted_content
    shutil.move(local_file_of, local_file_nf)
  File "C:\Python27\lib\shutil.py", line 303, in move
    os.unlink(src)
WindowsError: [Error 32] The process cannot access the file because it is being used by another process: u'C:\\\\Users\\\\lester.john\\\\Documents\\\\NetBeansProjects\\\\logs-downloader\\\\config\\448_30634.log'

2016-06-10 00:52:51,401 INFO Saved file 448_30634.log locally to the 'fail' folder
2016-06-10 00:52:51,410 WARNING Skipping File 448_30634.log
2016-06-10 00:52:52,000 INFO Successfully downloaded file from URL https://logs1.incapsula.com/448_290059/448_30635.log
2016-06-10 00:52:52,160 INFO Saving file 448_30635.log locally to the 'fail' folder  Traceback (most recent call last):
  File "LogsDownloader.py", line 198, in handle_file
    self.handle_log_decrypted_content(logfile, decrypted_file)
  File "LogsDownloader.py", line 244, in handle_log_decrypted_content
    shutil.move(local_file_of, local_file_nf)
  File "C:\Python27\lib\shutil.py", line 303, in move
    os.unlink(src)
WindowsError: [Error 32] The process cannot access the file because it is being used by another process: u'C:\\\\Users\\\\lester.john\\\\Documents\\\\NetBeansProjects\\\\logs-downloader\\\\config\\448_30635.log'

2016-06-10 00:52:52,184 INFO Saved file 448_30635.log locally to the 'fail' folder
2016-06-10 00:52:52,190 WARNING Skipping File 448_30635.log
2016-06-10 00:52:52,604 INFO Successfully downloaded file from URL https://logs1.incapsula.com/448_290059/448_30636.log
2016-06-10 00:52:52,631 INFO Saving file 448_30636.log locally to the 'fail' folder  Traceback (most recent call last):
  File "LogsDownloader.py", line 198, in handle_file
    self.handle_log_decrypted_content(logfile, decrypted_file)
  File "LogsDownloader.py", line 244, in handle_log_decrypted_content
    shutil.move(local_file_of, local_file_nf)
  File "C:\Python27\lib\shutil.py", line 303, in move
    os.unlink(src)
WindowsError: [Error 32] The process cannot access the file because it is being used by another process: u'C:\\\\Users\\\\lester.john\\\\Documents\\\\NetBeansProjects\\\\logs-downloader\\\\config\\448_30636.log'

2016-06-10 00:52:52,645 INFO Saved file 448_30636.log locally to the 'fail' folder
2016-06-10 00:52:52,648 WARNING Skipping File 448_30636.log
2016-06-10 00:52:53,115 INFO Successfully downloaded file from URL https://logs1.incapsula.com/448_290059/448_30637.log
2016-06-10 00:52:53,214 INFO Saving file 448_30637.log locally to the 'fail' folder  Traceback (most recent call last):
  File "LogsDownloader.py", line 198, in handle_file
    self.handle_log_decrypted_content(logfile, decrypted_file)
  File "LogsDownloader.py", line 244, in handle_log_decrypted_content
    shutil.move(local_file_of, local_file_nf)
  File "C:\Python27\lib\shutil.py", line 303, in move
    os.unlink(src)
WindowsError: [Error 32] The process cannot access the file because it is being used by another process: u'C:\\\\Users\\\\lester.john\\\\Documents\\\\NetBeansProjects\\\\logs-downloader\\\\config\\448_30637.log'

2016-06-10 00:52:53,230 INFO Saved file 448_30637.log locally to the 'fail' folder
2016-06-10 00:52:53,234 WARNING Skipping File 448_30637.log
2016-06-10 00:52:53,648 INFO Successfully downloaded file from URL https://logs1.incapsula.com/448_290059/448_30638.log
2016-06-10 00:52:53,749 INFO Saving file 448_30638.log locally to the 'fail' folder  Traceback (most recent call last):
  File "LogsDownloader.py", line 198, in handle_file
    self.handle_log_decrypted_content(logfile, decrypted_file)
  File "LogsDownloader.py", line 244, in handle_log_decrypted_content
    shutil.move(local_file_of, local_file_nf)
  File "C:\Python27\lib\shutil.py", line 303, in move
    os.unlink(src)
WindowsError: [Error 32] The process cannot access the file because it is being used by another process: u'C:\\\\Users\\\\lester.john\\\\Documents\\\\NetBeansProjects\\\\logs-downloader\\\\config\\448_30638.log'

2016-06-10 00:52:53,766 INFO Saved file 448_30638.log locally to the 'fail' folder
2016-06-10 00:52:53,770 WARNING Skipping File 448_30638.log
2016-06-10 00:52:54,260 INFO Successfully downloaded file from URL https://logs1.incapsula.com/448_290059/448_30639.log
2016-06-10 00:52:54,496 INFO Saving file 448_30639.log locally to the 'fail' folder  Traceback (most recent call last):
  File "LogsDownloader.py", line 198, in handle_file
    self.handle_log_decrypted_content(logfile, decrypted_file)
  File "LogsDownloader.py", line 244, in handle_log_decrypted_content
    shutil.move(local_file_of, local_file_nf)
  File "C:\Python27\lib\shutil.py", line 303, in move
    os.unlink(src)
WindowsError: [Error 32] The process cannot access the file because it is being used by another process: u'C:\\\\Users\\\\lester.john\\\\Documents\\\\NetBeansProjects\\\\logs-downloader\\\\config\\448_30639.log'

2016-06-10 00:52:54,536 INFO Saved file 448_30639.log locally to the 'fail' folder
2016-06-10 00:52:54,562 WARNING Skipping File 448_30639.log
2016-06-10 00:52:55,176 INFO Successfully downloaded file from URL https://logs1.incapsula.com/448_290059/448_30640.log
2016-06-10 00:52:55,709 INFO Saving file 448_30640.log locally to the 'fail' folder  Traceback (most recent call last):
  File "LogsDownloader.py", line 198, in handle_file
    self.handle_log_decrypted_content(logfile, decrypted_file)
  File "LogsDownloader.py", line 244, in handle_log_decrypted_content
    shutil.move(local_file_of, local_file_nf)
  File "C:\Python27\lib\shutil.py", line 303, in move
    os.unlink(src)
WindowsError: [Error 32] The process cannot access the file because it is being used by another process: u'C:\\\\Users\\\\lester.john\\\\Documents\\\\NetBeansProjects\\\\logs-downloader\\\\config\\448_30640.log'

2016-06-10 00:52:55,733 INFO Saved file 448_30640.log locally to the 'fail' folder
2016-06-10 00:52:55,740 WARNING Skipping File 448_30640.log
2016-06-10 00:52:56,573 INFO Successfully downloaded file from URL https://logs1.incapsula.com/448_290059/448_30641.log
2016-06-10 00:52:57,289 INFO Saving file 448_30641.log locally to the 'fail' folder  Traceback (most recent call last):
  File "LogsDownloader.py", line 198, in handle_file
    self.handle_log_decrypted_content(logfile, decrypted_file)
  File "LogsDownloader.py", line 244, in handle_log_decrypted_content
    shutil.move(local_file_of, local_file_nf)
  File "C:\Python27\lib\shutil.py", line 303, in move
    os.unlink(src)
WindowsError: [Error 32] The process cannot access the file because it is being used by another process: u'C:\\\\Users\\\\lester.john\\\\Documents\\\\NetBeansProjects\\\\logs-downloader\\\\config\\448_30641.log'

2016-06-10 00:52:57,312 INFO Saved file 448_30641.log locally to the 'fail' folder
2016-06-10 00:52:57,319 WARNING Skipping File 448_30641.log
2016-06-10 00:52:57,724 INFO Successfully downloaded file from URL https://logs1.incapsula.com/448_290059/448_30642.log
2016-06-10 00:52:57,744 INFO Saving file 448_30642.log locally to the 'fail' folder  Traceback (most recent call last):
  File "LogsDownloader.py", line 198, in handle_file
    self.handle_log_decrypted_content(logfile, decrypted_file)
  File "LogsDownloader.py", line 244, in handle_log_decrypted_content
    shutil.move(local_file_of, local_file_nf)
  File "C:\Python27\lib\shutil.py", line 303, in move
    os.unlink(src)
WindowsError: [Error 32] The process cannot access the file because it is being used by another process: u'C:\\\\Users\\\\lester.john\\\\Documents\\\\NetBeansProjects\\\\logs-downloader\\\\config\\448_30642.log'

2016-06-10 00:52:57,773 INFO Saved file 448_30642.log locally to the 'fail' folder
2016-06-10 00:52:57,779 WARNING Skipping File 448_30642.log
2016-06-10 00:52:58,282 INFO Successfully downloaded file from URL https://logs1.incapsula.com/448_290059/448_30643.log
2016-06-10 00:52:58,630 INFO Saving file 448_30643.log locally to the 'fail' folder  Traceback (most recent call last):
  File "LogsDownloader.py", line 198, in handle_file
    self.handle_log_decrypted_content(logfile, decrypted_file)
  File "LogsDownloader.py", line 244, in handle_log_decrypted_content
    shutil.move(local_file_of, local_file_nf)
  File "C:\Python27\lib\shutil.py", line 303, in move
    os.unlink(src)
WindowsError: [Error 32] The process cannot access the file because it is being used by another process: u'C:\\\\Users\\\\lester.john\\\\Documents\\\\NetBeansProjects\\\\logs-downloader\\\\config\\448_30643.log'

2016-06-10 00:52:58,653 INFO Saved file 448_30643.log locally to the 'fail' folder
2016-06-10 00:52:58,660 WARNING Skipping File 448_30643.log
2016-06-10 00:52:59,325 INFO Successfully downloaded file from URL https://logs1.incapsula.com/448_290059/448_30644.log
2016-06-10 00:52:59,437 INFO Saving file 448_30644.log locally to the 'fail' folder  Traceback (most recent call last):
  File "LogsDownloader.py", line 198, in handle_file
    self.handle_log_decrypted_content(logfile, decrypted_file)
  File "LogsDownloader.py", line 244, in handle_log_decrypted_content
    shutil.move(local_file_of, local_file_nf)
  File "C:\Python27\lib\shutil.py", line 303, in move
    os.unlink(src)
WindowsError: [Error 32] The process cannot access the file because it is being used by another process: u'C:\\\\Users\\\\lester.john\\\\Documents\\\\NetBeansProjects\\\\logs-downloader\\\\config\\448_30644.log'

2016-06-10 00:52:59,457 INFO Saved file 448_30644.log locally to the 'fail' folder
2016-06-10 00:52:59,463 WARNING Skipping File 448_30644.log
2016-06-10 00:52:59,846 INFO Successfully downloaded file from URL https://logs1.incapsula.com/448_290059/448_30645.log
2016-06-10 00:53:00,387 INFO Saving file 448_30645.log locally to the 'fail' folder  Traceback (most recent call last):
  File "LogsDownloader.py", line 198, in handle_file
    self.handle_log_decrypted_content(logfile, decrypted_file)
  File "LogsDownloader.py", line 244, in handle_log_decrypted_content
    shutil.move(local_file_of, local_file_nf)
  File "C:\Python27\lib\shutil.py", line 303, in move
    os.unlink(src)
WindowsError: [Error 32] The process cannot access the file because it is being used by another process: u'C:\\\\Users\\\\lester.john\\\\Documents\\\\NetBeansProjects\\\\logs-downloader\\\\config\\448_30645.log'

2016-06-10 00:53:00,410 INFO Saved file 448_30645.log locally to the 'fail' folder
2016-06-10 00:53:00,414 WARNING Skipping File 448_30645.log
2016-06-10 00:53:00,915 INFO Successfully downloaded file from URL https://logs1.incapsula.com/448_290059/448_30646.log
2016-06-10 00:53:01,078 INFO Saving file 448_30646.log locally to the 'fail' folder  Traceback (most recent call last):
  File "LogsDownloader.py", line 198, in handle_file
    self.handle_log_decrypted_content(logfile, decrypted_file)
  File "LogsDownloader.py", line 244, in handle_log_decrypted_content
    shutil.move(local_file_of, local_file_nf)
  File "C:\Python27\lib\shutil.py", line 303, in move
    os.unlink(src)
WindowsError: [Error 32] The process cannot access the file because it is being used by another process: u'C:\\\\Users\\\\lester.john\\\\Documents\\\\NetBeansProjects\\\\logs-downloader\\\\config\\448_30646.log'

2016-06-10 00:53:01,819 INFO Saved file 448_30646.log locally to the 'fail' folder
2016-06-10 00:53:01,828 WARNING Skipping File 448_30646.log
2016-06-10 00:53:02,375 INFO Successfully downloaded file from URL https://logs1.incapsula.com/448_290059/448_30647.log
2016-06-10 00:53:02,493 INFO Saving file 448_30647.log locally to the 'fail' folder  Traceback (most recent call last):
  File "LogsDownloader.py", line 198, in handle_file
    self.handle_log_decrypted_content(logfile, decrypted_file)
  File "LogsDownloader.py", line 244, in handle_log_decrypted_content
    shutil.move(local_file_of, local_file_nf)
  File "C:\Python27\lib\shutil.py", line 303, in move
    os.unlink(src)
WindowsError: [Error 32] The process cannot access the file because it is being used by another process: u'C:\\\\Users\\\\lester.john\\\\Documents\\\\NetBeansProjects\\\\logs-downloader\\\\config\\448_30647.log'

2016-06-10 00:53:02,515 INFO Saved file 448_30647.log locally to the 'fail' folder
2016-06-10 00:53:02,517 WARNING Skipping File 448_30647.log
2016-06-10 00:53:02,986 INFO Successfully downloaded file from URL https://logs1.incapsula.com/448_290059/448_30648.log
2016-06-10 00:53:03,088 INFO Saving file 448_30648.log locally to the 'fail' folder  Traceback (most recent call last):
  File "LogsDownloader.py", line 198, in handle_file
    self.handle_log_decrypted_content(logfile, decrypted_file)
  File "LogsDownloader.py", line 244, in handle_log_decrypted_content
    shutil.move(local_file_of, local_file_nf)
  File "C:\Python27\lib\shutil.py", line 303, in move
    os.unlink(src)
WindowsError: [Error 32] The process cannot access the file because it is being used by another process: u'C:\\\\Users\\\\lester.john\\\\Documents\\\\NetBeansProjects\\\\logs-downloader\\\\config\\448_30648.log'

2016-06-10 00:53:03,115 INFO Saved file 448_30648.log locally to the 'fail' folder
2016-06-10 00:53:03,122 WARNING Skipping File 448_30648.log
2016-06-10 00:53:03,677 INFO Successfully downloaded file from URL https://logs1.incapsula.com/448_290059/448_30649.log
2016-06-10 00:53:03,822 INFO Saving file 448_30649.log locally to the 'fail' folder  Traceback (most recent call last):
  File "LogsDownloader.py", line 198, in handle_file
    self.handle_log_decrypted_content(logfile, decrypted_file)
  File "LogsDownloader.py", line 244, in handle_log_decrypted_content
    shutil.move(local_file_of, local_file_nf)
  File "C:\Python27\lib\shutil.py", line 303, in move
    os.unlink(src)
WindowsError: [Error 32] The process cannot access the file because it is being used by another process: u'C:\\\\Users\\\\lester.john\\\\Documents\\\\NetBeansProjects\\\\logs-downloader\\\\config\\448_30649.log'

2016-06-10 00:53:03,845 INFO Saved file 448_30649.log locally to the 'fail' folder
2016-06-10 00:53:03,848 WARNING Skipping File 448_30649.log
2016-06-10 00:53:04,233 INFO Successfully downloaded file from URL https://logs1.incapsula.com/448_290059/448_30650.log
2016-06-10 00:53:05,408 INFO Saving file 448_30650.log locally to the 'fail' folder  Traceback (most recent call last):
  File "LogsDownloader.py", line 198, in handle_file
    self.handle_log_decrypted_content(logfile, decrypted_file)
  File "LogsDownloader.py", line 244, in handle_log_decrypted_content
    shutil.move(local_file_of, local_file_nf)
  File "C:\Python27\lib\shutil.py", line 303, in move
    os.unlink(src)
WindowsError: [Error 32] The process cannot access the file because it is being used by another process: u'C:\\\\Users\\\\lester.john\\\\Documents\\\\NetBeansProjects\\\\logs-downloader\\\\config\\448_30650.log'

2016-06-10 00:53:05,441 INFO Saved file 448_30650.log locally to the 'fail' folder
2016-06-10 00:53:05,450 WARNING Skipping File 448_30650.log
2016-06-10 00:53:05,885 INFO Successfully downloaded file from URL https://logs1.incapsula.com/448_290059/448_30651.log
2016-06-10 00:53:06,240 INFO Saving file 448_30651.log locally to the 'fail' folder  Traceback (most recent call last):
  File "LogsDownloader.py", line 198, in handle_file
    self.handle_log_decrypted_content(logfile, decrypted_file)
  File "LogsDownloader.py", line 244, in handle_log_decrypted_content
    shutil.move(local_file_of, local_file_nf)
  File "C:\Python27\lib\shutil.py", line 303, in move
    os.unlink(src)
WindowsError: [Error 32] The process cannot access the file because it is being used by another process: u'C:\\\\Users\\\\lester.john\\\\Documents\\\\NetBeansProjects\\\\logs-downloader\\\\config\\448_30651.log'

2016-06-10 00:53:06,259 INFO Saved file 448_30651.log locally to the 'fail' folder
2016-06-10 00:53:06,263 WARNING Skipping File 448_30651.log
2016-06-10 00:53:06,627 INFO Successfully downloaded file from URL https://logs1.incapsula.com/448_290059/448_30652.log
2016-06-10 00:53:06,752 INFO Saving file 448_30652.log locally to the 'fail' folder  Traceback (most recent call last):
  File "LogsDownloader.py", line 198, in handle_file
    self.handle_log_decrypted_content(logfile, decrypted_file)
  File "LogsDownloader.py", line 244, in handle_log_decrypted_content
    shutil.move(local_file_of, local_file_nf)
  File "C:\Python27\lib\shutil.py", line 303, in move
    os.unlink(src)
WindowsError: [Error 32] The process cannot access the file because it is being used by another process: u'C:\\\\Users\\\\lester.john\\\\Documents\\\\NetBeansProjects\\\\logs-downloader\\\\config\\448_30652.log'

2016-06-10 00:53:06,766 INFO Saved file 448_30652.log locally to the 'fail' folder
2016-06-10 00:53:06,769 WARNING Skipping File 448_30652.log
2016-06-10 00:53:07,154 INFO Successfully downloaded file from URL https://logs1.incapsula.com/448_290059/448_30653.log
2016-06-10 00:53:07,236 INFO Saving file 448_30653.log locally to the 'fail' folder  Traceback (most recent call last):
  File "LogsDownloader.py", line 198, in handle_file
    self.handle_log_decrypted_content(logfile, decrypted_file)
  File "LogsDownloader.py", line 244, in handle_log_decrypted_content
    shutil.move(local_file_of, local_file_nf)
  File "C:\Python27\lib\shutil.py", line 303, in move
    os.unlink(src)
WindowsError: [Error 32] The process cannot access the file because it is being used by another process: u'C:\\\\Users\\\\lester.john\\\\Documents\\\\NetBeansProjects\\\\logs-downloader\\\\config\\448_30653.log'

2016-06-10 00:53:07,250 INFO Saved file 448_30653.log locally to the 'fail' folder
2016-06-10 00:53:07,253 WARNING Skipping File 448_30653.log
2016-06-10 00:53:07,799 INFO Successfully downloaded file from URL https://logs1.incapsula.com/448_290059/448_30654.log
2016-06-10 00:53:07,917 INFO Saving file 448_30654.log locally to the 'fail' folder  Traceback (most recent call last):
  File "LogsDownloader.py", line 198, in handle_file
    self.handle_log_decrypted_content(logfile, decrypted_file)
  File "LogsDownloader.py", line 244, in handle_log_decrypted_content
    shutil.move(local_file_of, local_file_nf)
  File "C:\Python27\lib\shutil.py", line 303, in move
    os.unlink(src)
WindowsError: [Error 32] The process cannot access the file because it is being used by another process: u'C:\\\\Users\\\\lester.john\\\\Documents\\\\NetBeansProjects\\\\logs-downloader\\\\config\\448_30654.log'

2016-06-10 00:53:07,946 INFO Saved file 448_30654.log locally to the 'fail' folder
2016-06-10 00:53:07,966 WARNING Skipping File 448_30654.log
2016-06-10 00:53:08,388 INFO Successfully downloaded file from URL https://logs1.incapsula.com/448_290059/448_30655.log
2016-06-10 00:53:08,512 INFO Saving file 448_30655.log locally to the 'fail' folder  Traceback (most recent call last):
  File "LogsDownloader.py", line 198, in handle_file
    self.handle_log_decrypted_content(logfile, decrypted_file)
  File "LogsDownloader.py", line 244, in handle_log_decrypted_content
    shutil.move(local_file_of, local_file_nf)
  File "C:\Python27\lib\shutil.py", line 303, in move
    os.unlink(src)
WindowsError: [Error 32] The process cannot access the file because it is being used by another process: u'C:\\\\Users\\\\lester.john\\\\Documents\\\\NetBeansProjects\\\\logs-downloader\\\\config\\448_30655.log'

2016-06-10 00:53:08,542 INFO Saved file 448_30655.log locally to the 'fail' folder
2016-06-10 00:53:08,655 WARNING Skipping File 448_30655.log
2016-06-10 00:53:09,040 INFO Successfully downloaded file from URL https://logs1.incapsula.com/448_290059/448_30656.log
2016-06-10 00:53:09,464 INFO Saving file 448_30656.log locally to the 'fail' folder  Traceback (most recent call last):
  File "LogsDownloader.py", line 198, in handle_file
    self.handle_log_decrypted_content(logfile, decrypted_file)
  File "LogsDownloader.py", line 244, in handle_log_decrypted_content
    shutil.move(local_file_of, local_file_nf)
  File "C:\Python27\lib\shutil.py", line 303, in move
    os.unlink(src)
WindowsError: [Error 32] The process cannot access the file because it is being used by another process: u'C:\\\\Users\\\\lester.john\\\\Documents\\\\NetBeansProjects\\\\logs-downloader\\\\config\\448_30656.log'

2016-06-10 00:53:09,950 INFO Saved file 448_30656.log locally to the 'fail' folder
2016-06-10 00:53:09,990 WARNING Skipping File 448_30656.log
2016-06-10 00:53:10,654 INFO Successfully downloaded file from URL https://logs1.incapsula.com/448_290059/448_30657.log
2016-06-10 00:53:10,848 INFO Saving file 448_30657.log locally to the 'fail' folder  Traceback (most recent call last):
  File "LogsDownloader.py", line 198, in handle_file
    self.handle_log_decrypted_content(logfile, decrypted_file)
  File "LogsDownloader.py", line 244, in handle_log_decrypted_content
    shutil.move(local_file_of, local_file_nf)
  File "C:\Python27\lib\shutil.py", line 303, in move
    os.unlink(src)
WindowsError: [Error 32] The process cannot access the file because it is being used by another process: u'C:\\\\Users\\\\lester.john\\\\Documents\\\\NetBeansProjects\\\\logs-downloader\\\\config\\448_30657.log'

2016-06-10 00:53:10,868 INFO Saved file 448_30657.log locally to the 'fail' folder
2016-06-10 00:53:10,872 WARNING Skipping File 448_30657.log
2016-06-10 00:53:12,032 INFO Successfully downloaded file from URL https://logs1.incapsula.com/448_290059/448_30658.log
2016-06-10 00:53:12,098 INFO Saving file 448_30658.log locally to the 'fail' folder  Traceback (most recent call last):
  File "LogsDownloader.py", line 198, in handle_file
    self.handle_log_decrypted_content(logfile, decrypted_file)
  File "LogsDownloader.py", line 244, in handle_log_decrypted_content
    shutil.move(local_file_of, local_file_nf)
  File "C:\Python27\lib\shutil.py", line 303, in move
    os.unlink(src)
WindowsError: [Error 32] The process cannot access the file because it is being used by another process: u'C:\\\\Users\\\\lester.john\\\\Documents\\\\NetBeansProjects\\\\logs-downloader\\\\config\\448_30658.log'

2016-06-10 00:53:12,125 INFO Saved file 448_30658.log locally to the 'fail' folder
2016-06-10 00:53:12,137 WARNING Skipping File 448_30658.log
2016-06-10 00:53:13,079 INFO Successfully downloaded file from URL https://logs1.incapsula.com/448_290059/448_30659.log
2016-06-10 00:53:13,236 INFO Saving file 448_30659.log locally to the 'fail' folder  Traceback (most recent call last):
  File "LogsDownloader.py", line 198, in handle_file
    self.handle_log_decrypted_content(logfile, decrypted_file)
  File "LogsDownloader.py", line 244, in handle_log_decrypted_content
    shutil.move(local_file_of, local_file_nf)
  File "C:\Python27\lib\shutil.py", line 303, in move
    os.unlink(src)
WindowsError: [Error 32] The process cannot access the file because it is being used by another process: u'C:\\\\Users\\\\lester.john\\\\Documents\\\\NetBeansProjects\\\\logs-downloader\\\\config\\448_30659.log'

2016-06-10 00:53:13,259 INFO Saved file 448_30659.log locally to the 'fail' folder
2016-06-10 00:53:13,266 WARNING Skipping File 448_30659.log
2016-06-10 00:53:13,757 INFO Successfully downloaded file from URL https://logs1.incapsula.com/448_290059/448_30660.log
2016-06-10 00:53:14,617 INFO Saving file 448_30660.log locally to the 'fail' folder  Traceback (most recent call last):
  File "LogsDownloader.py", line 198, in handle_file
    self.handle_log_decrypted_content(logfile, decrypted_file)
  File "LogsDownloader.py", line 244, in handle_log_decrypted_content
    shutil.move(local_file_of, local_file_nf)
  File "C:\Python27\lib\shutil.py", line 303, in move
    os.unlink(src)
WindowsError: [Error 32] The process cannot access the file because it is being used by another process: u'C:\\\\Users\\\\lester.john\\\\Documents\\\\NetBeansProjects\\\\logs-downloader\\\\config\\448_30660.log'

2016-06-10 00:53:14,644 INFO Saved file 448_30660.log locally to the 'fail' folder
2016-06-10 00:53:14,661 WARNING Skipping File 448_30660.log
2016-06-10 00:53:15,117 INFO Successfully downloaded file from URL https://logs1.incapsula.com/448_290059/448_30661.log
2016-06-10 00:53:15,598 INFO Saving file 448_30661.log locally to the 'fail' folder  Traceback (most recent call last):
  File "LogsDownloader.py", line 198, in handle_file
    self.handle_log_decrypted_content(logfile, decrypted_file)
  File "LogsDownloader.py", line 244, in handle_log_decrypted_content
    shutil.move(local_file_of, local_file_nf)
  File "C:\Python27\lib\shutil.py", line 303, in move
    os.unlink(src)
WindowsError: [Error 32] The process cannot access the file because it is being used by another process: u'C:\\\\Users\\\\lester.john\\\\Documents\\\\NetBeansProjects\\\\logs-downloader\\\\config\\448_30661.log'

2016-06-10 00:53:15,618 INFO Saved file 448_30661.log locally to the 'fail' folder
2016-06-10 00:53:15,625 WARNING Skipping File 448_30661.log
2016-06-10 00:53:16,042 INFO Successfully downloaded file from URL https://logs1.incapsula.com/448_290059/448_30662.log
2016-06-10 00:53:16,380 INFO Saving file 448_30662.log locally to the 'fail' folder  Traceback (most recent call last):
  File "LogsDownloader.py", line 198, in handle_file
    self.handle_log_decrypted_content(logfile, decrypted_file)
  File "LogsDownloader.py", line 244, in handle_log_decrypted_content
    shutil.move(local_file_of, local_file_nf)
  File "C:\Python27\lib\shutil.py", line 303, in move
    os.unlink(src)
WindowsError: [Error 32] The process cannot access the file because it is being used by another process: u'C:\\\\Users\\\\lester.john\\\\Documents\\\\NetBeansProjects\\\\logs-downloader\\\\config\\448_30662.log'

2016-06-10 00:53:16,401 INFO Saved file 448_30662.log locally to the 'fail' folder
2016-06-10 00:53:16,404 WARNING Skipping File 448_30662.log
2016-06-10 00:53:16,943 INFO Successfully downloaded file from URL https://logs1.incapsula.com/448_290059/448_30663.log
2016-06-10 00:53:17,033 INFO Saving file 448_30663.log locally to the 'fail' folder  Traceback (most recent call last):
  File "LogsDownloader.py", line 198, in handle_file
    self.handle_log_decrypted_content(logfile, decrypted_file)
  File "LogsDownloader.py", line 244, in handle_log_decrypted_content
    shutil.move(local_file_of, local_file_nf)
  File "C:\Python27\lib\shutil.py", line 303, in move
    os.unlink(src)
WindowsError: [Error 32] The process cannot access the file because it is being used by another process: u'C:\\\\Users\\\\lester.john\\\\Documents\\\\NetBeansProjects\\\\logs-downloader\\\\config\\448_30663.log'

2016-06-10 00:53:17,055 INFO Saved file 448_30663.log locally to the 'fail' folder
2016-06-10 00:53:17,058 WARNING Skipping File 448_30663.log
2016-06-10 00:53:17,482 INFO Successfully downloaded file from URL https://logs1.incapsula.com/448_290059/448_30664.log
2016-06-10 00:53:17,595 INFO Saving file 448_30664.log locally to the 'fail' folder  Traceback (most recent call last):
  File "LogsDownloader.py", line 198, in handle_file
    self.handle_log_decrypted_content(logfile, decrypted_file)
  File "LogsDownloader.py", line 244, in handle_log_decrypted_content
    shutil.move(local_file_of, local_file_nf)
  File "C:\Python27\lib\shutil.py", line 303, in move
    os.unlink(src)
WindowsError: [Error 32] The process cannot access the file because it is being used by another process: u'C:\\\\Users\\\\lester.john\\\\Documents\\\\NetBeansProjects\\\\logs-downloader\\\\config\\448_30664.log'

2016-06-10 00:53:17,624 INFO Saved file 448_30664.log locally to the 'fail' folder
2016-06-10 00:53:17,631 WARNING Skipping File 448_30664.log
2016-06-10 00:53:18,055 INFO Successfully downloaded file from URL https://logs1.incapsula.com/448_290059/448_30665.log
2016-06-10 00:53:19,201 INFO Saving file 448_30665.log locally to the 'fail' folder  Traceback (most recent call last):
  File "LogsDownloader.py", line 198, in handle_file
    self.handle_log_decrypted_content(logfile, decrypted_file)
  File "LogsDownloader.py", line 244, in handle_log_decrypted_content
    shutil.move(local_file_of, local_file_nf)
  File "C:\Python27\lib\shutil.py", line 303, in move
    os.unlink(src)
WindowsError: [Error 32] The process cannot access the file because it is being used by another process: u'C:\\\\Users\\\\lester.john\\\\Documents\\\\NetBeansProjects\\\\logs-downloader\\\\config\\448_30665.log'

2016-06-10 00:53:19,226 INFO Saved file 448_30665.log locally to the 'fail' folder
2016-06-10 00:53:19,230 WARNING Skipping File 448_30665.log
2016-06-10 00:53:19,676 INFO Successfully downloaded file from URL https://logs1.incapsula.com/448_290059/448_30666.log
2016-06-10 00:53:20,302 INFO Saving file 448_30666.log locally to the 'fail' folder  Traceback (most recent call last):
  File "LogsDownloader.py", line 198, in handle_file
    self.handle_log_decrypted_content(logfile, decrypted_file)
  File "LogsDownloader.py", line 244, in handle_log_decrypted_content
    shutil.move(local_file_of, local_file_nf)
  File "C:\Python27\lib\shutil.py", line 303, in move
    os.unlink(src)
WindowsError: [Error 32] The process cannot access the file because it is being used by another process: u'C:\\\\Users\\\\lester.john\\\\Documents\\\\NetBeansProjects\\\\logs-downloader\\\\config\\448_30666.log'

2016-06-10 00:53:20,312 INFO Saved file 448_30666.log locally to the 'fail' folder
2016-06-10 00:53:20,318 WARNING Skipping File 448_30666.log
2016-06-10 00:53:20,723 INFO Successfully downloaded file from URL https://logs1.incapsula.com/448_290059/448_30667.log
2016-06-10 00:53:20,742 INFO Saving file 448_30667.log locally to the 'fail' folder  Traceback (most recent call last):
  File "LogsDownloader.py", line 198, in handle_file
    self.handle_log_decrypted_content(logfile, decrypted_file)
  File "LogsDownloader.py", line 244, in handle_log_decrypted_content
    shutil.move(local_file_of, local_file_nf)
  File "C:\Python27\lib\shutil.py", line 303, in move
    os.unlink(src)
WindowsError: [Error 32] The process cannot access the file because it is being used by another process: u'C:\\\\Users\\\\lester.john\\\\Documents\\\\NetBeansProjects\\\\logs-downloader\\\\config\\448_30667.log'

2016-06-10 00:53:20,769 INFO Saved file 448_30667.log locally to the 'fail' folder
2016-06-10 00:53:20,789 WARNING Skipping File 448_30667.log
2016-06-10 00:53:21,256 INFO Successfully downloaded file from URL https://logs1.incapsula.com/448_290059/448_30668.log
2016-06-10 00:53:21,381 INFO Saving file 448_30668.log locally to the 'fail' folder  Traceback (most recent call last):
  File "LogsDownloader.py", line 198, in handle_file
    self.handle_log_decrypted_content(logfile, decrypted_file)
  File "LogsDownloader.py", line 244, in handle_log_decrypted_content
    shutil.move(local_file_of, local_file_nf)
  File "C:\Python27\lib\shutil.py", line 303, in move
    os.unlink(src)
WindowsError: [Error 32] The process cannot access the file because it is being used by another process: u'C:\\\\Users\\\\lester.john\\\\Documents\\\\NetBeansProjects\\\\logs-downloader\\\\config\\448_30668.log'

2016-06-10 00:53:21,401 INFO Saved file 448_30668.log locally to the 'fail' folder
2016-06-10 00:53:21,408 WARNING Skipping File 448_30668.log
2016-06-10 00:53:21,982 INFO Successfully downloaded file from URL https://logs1.incapsula.com/448_290059/448_30669.log
2016-06-10 00:53:22,111 INFO Saving file 448_30669.log locally to the 'fail' folder  Traceback (most recent call last):
  File "LogsDownloader.py", line 198, in handle_file
    self.handle_log_decrypted_content(logfile, decrypted_file)
  File "LogsDownloader.py", line 244, in handle_log_decrypted_content
    shutil.move(local_file_of, local_file_nf)
  File "C:\Python27\lib\shutil.py", line 303, in move
    os.unlink(src)
WindowsError: [Error 32] The process cannot access the file because it is being used by another process: u'C:\\\\Users\\\\lester.john\\\\Documents\\\\NetBeansProjects\\\\logs-downloader\\\\config\\448_30669.log'

2016-06-10 00:53:22,135 INFO Saved file 448_30669.log locally to the 'fail' folder
2016-06-10 00:53:22,144 WARNING Skipping File 448_30669.log
2016-06-10 00:53:22,788 INFO Successfully downloaded file from URL https://logs1.incapsula.com/448_290059/448_30670.log
2016-06-10 00:53:23,138 INFO Saving file 448_30670.log locally to the 'fail' folder  Traceback (most recent call last):
  File "LogsDownloader.py", line 198, in handle_file
    self.handle_log_decrypted_content(logfile, decrypted_file)
  File "LogsDownloader.py", line 244, in handle_log_decrypted_content
    shutil.move(local_file_of, local_file_nf)
  File "C:\Python27\lib\shutil.py", line 303, in move
    os.unlink(src)
WindowsError: [Error 32] The process cannot access the file because it is being used by another process: u'C:\\\\Users\\\\lester.john\\\\Documents\\\\NetBeansProjects\\\\logs-downloader\\\\config\\448_30670.log'

2016-06-10 00:58:22,973 DEBUG Initializing LogsDownloader
2016-06-10 00:58:22,976 INFO LogsDownloader initializing is done
2016-06-10 00:58:22,979 INFO No last downloaded file is found - downloading index file and starting to download all the log files in it
2016-06-10 00:58:22,980 INFO Downloading logs index file...
2016-06-10 00:58:24,538 INFO Successfully downloaded file from URL https://logs1.incapsula.com/448_290059/logs.index
2016-06-10 00:58:24,832 INFO No last index found, will now scan the entire index...
2016-06-10 01:00:37,865 DEBUG Initializing LogsDownloader
2016-06-10 01:00:37,868 INFO LogsDownloader initializing is done
2016-06-10 01:00:37,871 INFO No last downloaded file is found - downloading index file and starting to download all the log files in it
2016-06-10 01:00:37,872 INFO Downloading logs index file...
2016-06-10 01:00:39,301 INFO Successfully downloaded file from URL https://logs1.incapsula.com/448_290059/logs.index
2016-06-10 01:00:39,802 INFO No last index found, will now scan the entire index...
2016-06-10 01:01:40,476 INFO Successfully downloaded file from URL https://logs1.incapsula.com/448_290059/448_30634.log
2016-06-10 01:01:40,999 INFO File 448_30634.log download and processing completed successfully
2016-06-10 01:02:41,746 INFO Successfully downloaded file from URL https://logs1.incapsula.com/448_290059/448_30635.log
2016-06-10 01:02:42,160 INFO File 448_30635.log download and processing completed successfully
2016-06-10 01:03:42,631 INFO Successfully downloaded file from URL https://logs1.incapsula.com/448_290059/448_30636.log
2016-06-10 01:03:42,815 INFO File 448_30636.log download and processing completed successfully
2016-06-10 01:04:43,446 INFO Successfully downloaded file from URL https://logs1.incapsula.com/448_290059/448_30637.log
2016-06-10 01:04:43,631 INFO File 448_30637.log download and processing completed successfully
2016-06-10 01:05:44,124 INFO Successfully downloaded file from URL https://logs1.incapsula.com/448_290059/448_30638.log
2016-06-10 01:05:44,244 INFO File 448_30638.log download and processing completed successfully
2016-06-10 01:06:45,029 INFO Successfully downloaded file from URL https://logs1.incapsula.com/448_290059/448_30639.log
2016-06-10 01:06:45,417 INFO File 448_30639.log download and processing completed successfully
2016-06-10 01:07:46,026 INFO Successfully downloaded file from URL https://logs1.incapsula.com/448_290059/448_30640.log
2016-06-10 01:07:46,565 INFO File 448_30640.log download and processing completed successfully
2016-06-10 01:08:46,974 INFO Successfully downloaded file from URL https://logs1.incapsula.com/448_290059/448_30641.log
2016-06-10 01:08:47,157 INFO File 448_30641.log download and processing completed successfully
